<sdf version='1.6'>
  <world name='default'>
    <light name='sun' type='directional'>
      <cast_shadows>1</cast_shadows>
      <pose frame=''>0 0 10 0 -0 0</pose>
      <diffuse>0.8 0.8 0.8 1</diffuse>
      <specular>0.2 0.2 0.2 1</specular>
      <attenuation>
        <range>1000</range>
        <constant>0.9</constant>
        <linear>0.01</linear>
        <quadratic>0.001</quadratic>
      </attenuation>
      <direction>-0.5 0.1 -0.9</direction>
    </light>
    <model name='ground_plane'>
      <static>1</static>
      <link name='link'>
        <collision name='collision'>
          <geometry>
            <plane>
              <normal>0 0 1</normal>
              <size>100 100</size>
            </plane>
          </geometry>
          <surface>
            <friction>
              <ode>
                <mu>100</mu>
                <mu2>50</mu2>
              </ode>
              <torsional>
                <ode/>
              </torsional>
            </friction>
            <contact>
              <ode/>
            </contact>
            <bounce/>
          </surface>
          <max_contacts>10</max_contacts>
        </collision>
        <visual name='visual'>
          <cast_shadows>0</cast_shadows>
          <geometry>
            <plane>
              <normal>0 0 1</normal>
              <size>100 100</size>
            </plane>
          </geometry>
          <material>
            <script>
              <uri>file://media/materials/scripts/gazebo.material</uri>
              <name>Gazebo/Grey</name>
            </script>
          </material>
        </visual>
        <self_collide>0</self_collide>
        <enable_wind>0</enable_wind>
        <kinematic>0</kinematic>
      </link>
    </model>
    <gravity>0 0 -9.8</gravity>
    <magnetic_field>6e-06 2.3e-05 -4.2e-05</magnetic_field>
    <atmosphere type='adiabatic'/>
    <physics name='default_physics' default='0' type='ode'>
      <max_step_size>0.001</max_step_size>
      <real_time_factor>1</real_time_factor>
      <real_time_update_rate>1000</real_time_update_rate>
    </physics>
    <scene>
      <ambient>0.4 0.4 0.4 1</ambient>
      <background>0.7 0.7 0.7 1</background>
      <shadows>1</shadows>
    </scene>
    <audio>
      <device>default</device>
    </audio>
    <wind/>
    <spherical_coordinates>
      <surface_model>EARTH_WGS84</surface_model>
      <latitude_deg>0</latitude_deg>
      <longitude_deg>0</longitude_deg>
      <elevation>0</elevation>
      <heading_deg>0</heading_deg>
    </spherical_coordinates>
    <model name='apollo'>
      <link name='base_link'>
        <pose frame=''>0 0 0 0 -0 0</pose>
        <inertial>
          <pose frame=''>0.004609 0 0.00341 0 -0 0</pose>
          <mass>21.112</mass>
          <inertia>
            <ixx>0.174519</ixx>
            <ixy>0</ixy>
            <ixz>-0.0140686</ixz>
            <iyy>0.454898</iyy>
            <iyz>0</iyz>
            <izz>0.580339</izz>
          </inertia>
        </inertial>
        <collision name='base_link_collision'>
          <pose frame=''>0 0 0.05 0 -0 0</pose>
          <geometry>
            <box>
              <size>0.49492 0.3 0.09625</size>
            </box>
          </geometry>
          <max_contacts>10</max_contacts>
          <surface>
            <contact>
              <ode/>
            </contact>
            <bounce/>
            <friction>
              <torsional>
                <ode/>
              </torsional>
              <ode/>
            </friction>
          </surface>
        </collision>
        <collision name='base_link_fixed_joint_lump__fork_b_collision_1'>
          <pose frame=''>-0.01 0 0.395 0 -0 0</pose>
          <geometry>
            <box>
              <size>0.04 0.25 0.002</size>
            </box>
          </geometry>
          <max_contacts>10</max_contacts>
          <surface>
            <contact>
              <ode/>
            </contact>
            <bounce/>
            <friction>
              <torsional>
                <ode/>
              </torsional>
              <ode/>
            </friction>
          </surface>
        </collision>
        <collision name='base_link_fixed_joint_lump__kinect_link_collision_2'>
          <pose frame=''>0.2 0 0.1295 0 -0 0</pose>
          <geometry>
            <box>
              <size>0.07 0.3 0.09</size>
            </box>
          </geometry>
          <surface>
            <contact>
              <ode/>
            </contact>
            <friction>
              <ode/>
              <torsional>
                <ode/>
              </torsional>
            </friction>
            <bounce/>
          </surface>
          <max_contacts>10</max_contacts>
        </collision>
        <visual name='base_link_visual'>
          <pose frame=''>0 0 0 0 -0 0</pose>
          <geometry>
            <mesh>
              <scale>1 1 1</scale>
              <uri>/home/joe/test_ws/src/apollo/apollo_description/meshfiles/base_link.STL</uri>
            </mesh>
          </geometry>
        </visual>
        <visual name='base_link_fixed_joint_lump__fork_b_visual_1'>
          <pose frame=''>-0.025 0 0 0 -0 0</pose>
          <geometry>
            <mesh>
              <scale>1 1 1</scale>
              <uri>/home/joe/test_ws/src/apollo/apollo_description/meshfiles/lift_base_link.STL</uri>
            </mesh>
          </geometry>
        </visual>
        <visual name='base_link_fixed_joint_lump__kinect_link_visual_2'>
          <pose frame=''>0.2 0 0.1295 0 -0 1.5708</pose>
          <geometry>
            <mesh>
              <scale>1 1 1</scale>
              <uri>/opt/ros/melodic/share/husky_description/meshes/accessories/kinect.dae</uri>
            </mesh>
          </geometry>
          <material>
            <script>
              <uri>__default__</uri>
              <name>__default__</name>
            </script>
          </material>
        </visual>
        <velocity_decay/>
        <sensor name='front_ultrasonic_sen' type='ray'>
          <update_rate>50</update_rate>
          <ray>
            <scan>
              <horizontal>
                <samples>1</samples>
                <resolution>1</resolution>
                <min_angle>-0.1309</min_angle>
                <max_angle>0.1309</max_angle>
              </horizontal>
              <vertical>
                <samples>1</samples>
                <resolution>1</resolution>
                <min_angle>-0.01</min_angle>
                <max_angle>0.01</max_angle>
              </vertical>
            </scan>
            <range>
              <min>0.02</min>
              <max>2</max>
              <resolution>0.02</resolution>
            </range>
          </ray>
          <plugin name='gazebo_ros_range' filename='libgazebo_ros_range.so'>
            <gaussianNoise>0.005</gaussianNoise>
            <alwaysOn>1</alwaysOn>
            <updateRate>50</updateRate>
            <topicName>/front_ultrasonic</topicName>
            <frameName>front_ultrasonic</frameName>
            <visualize>1</visualize>
            <radiation>ultrasonic</radiation>
            <fov>0.261799</fov>
            <robotNamespace>/</robotNamespace>
          </plugin>
          <pose frame=''>0.24746 0 0 0 -0 0</pose>
        </sensor>
        <velocity_decay/>
        <sensor name='kinect' type='depth'>
          <always_on>1</always_on>
          <update_rate>200</update_rate>
          <camera name='__default__'>
            <horizontal_fov>1.0472</horizontal_fov>
            <image>
              <format>R8G8B8</format>
              <width>640</width>
              <height>480</height>
            </image>
            <clip>
              <near>0.05</near>
              <far>8</far>
            </clip>
          </camera>
          <plugin name='kinect_controller' filename='libgazebo_ros_openni_kinect.so'>
            <cameraName>kinect</cameraName>
            <alwaysOn>1</alwaysOn>
            <updateRate>0</updateRate>
            <imageTopicName>rgb/image_raw</imageTopicName>
            <depthImageTopicName>depth/image_raw</depthImageTopicName>
            <pointCloudTopicName>depth/points</pointCloudTopicName>
            <cameraInfoTopicName>rgb/camera_info</cameraInfoTopicName>
            <depthImageCameraInfoTopicName>depth/camera_info</depthImageCameraInfoTopicName>
            <frameName>kinect_frame_optical</frameName>
            <baseline>0.1</baseline>
            <distortion_k1>0.0</distortion_k1>
            <distortion_k2>0.0</distortion_k2>
            <distortion_k3>0.0</distortion_k3>
            <distortion_t1>0.0</distortion_t1>
            <distortion_t2>0.0</distortion_t2>
            <pointCloudCutoff>0.4</pointCloudCutoff>
            <robotNamespace>/</robotNamespace>
          </plugin>
          <pose frame=''>0.2 0 0.1295 0 -0 0</pose>
        </sensor>
        <gravity>1</gravity>
        <velocity_decay/>
        <sensor name='rear_ultrasonic_sen' type='ray'>
          <update_rate>50</update_rate>
          <ray>
            <scan>
              <horizontal>
                <samples>1</samples>
                <resolution>1</resolution>
                <min_angle>-0.1309</min_angle>
                <max_angle>0.1309</max_angle>
              </horizontal>
              <vertical>
                <samples>1</samples>
                <resolution>1</resolution>
                <min_angle>-0.01</min_angle>
                <max_angle>0.01</max_angle>
              </vertical>
            </scan>
            <range>
              <min>0.02</min>
              <max>2</max>
              <resolution>0.02</resolution>
            </range>
          </ray>
          <plugin name='gazebo_ros_range' filename='libgazebo_ros_range.so'>
            <gaussianNoise>0.005</gaussianNoise>
            <alwaysOn>1</alwaysOn>
            <updateRate>50</updateRate>
            <topicName>/rear_ultrasonic</topicName>
            <frameName>rear_ultrasonic</frameName>
            <visualize>1</visualize>
            <radiation>ultrasonic</radiation>
            <fov>0.261799</fov>
            <robotNamespace>/</robotNamespace>
          </plugin>
          <pose frame=''>-0.24746 0 0 0 -0 -3.14159</pose>
        </sensor>
        <self_collide>0</self_collide>
        <enable_wind>0</enable_wind>
        <kinematic>0</kinematic>
      </link>
      <link name='fork'>
        <pose frame=''>-0.003 0.12 0.097 0 -0 0</pose>
        <inertial>
          <pose frame=''>0 0 0 0 -0 0</pose>
          <mass>0.556</mass>
          <inertia>
            <ixx>0</ixx>
            <ixy>0</ixy>
            <ixz>0</ixz>
            <iyy>0</iyy>
            <iyz>0</iyz>
            <izz>0</izz>
          </inertia>
        </inertial>
        <collision name='fork_collision'>
          <pose frame=''>0 0 0 0 0 -1.5708</pose>
          <geometry>
            <mesh>
              <scale>1 1 1</scale>
              <uri>/home/joe/test_ws/src/apollo/apollo_description/meshfiles/fork_collider.stl</uri>
            </mesh>
          </geometry>
          <surface>
            <contact>
              <ode/>
            </contact>
            <friction>
              <ode/>
              <torsional>
                <ode/>
              </torsional>
            </friction>
            <bounce/>
          </surface>
          <max_contacts>10</max_contacts>
        </collision>
        <visual name='fork_visual'>
          <pose frame=''>0 0 0 0 0 -1.5708</pose>
          <geometry>
            <mesh>
              <scale>1 1 1</scale>
              <uri>/home/joe/test_ws/src/apollo/apollo_description/meshfiles/fork_link.STL</uri>
            </mesh>
          </geometry>
          <material>
            <script>
              <uri>__default__</uri>
              <name>__default__</name>
            </script>
          </material>
        </visual>
        <gravity>0</gravity>
        <velocity_decay/>
        <self_collide>0</self_collide>
        <enable_wind>0</enable_wind>
        <kinematic>0</kinematic>
      </link>
      <joint name='fork_joint' type='prismatic'>
        <child>fork</child>
        <parent>base_link</parent>
        <axis>
          <xyz>0 0 1</xyz>
          <limit>
            <lower>0</lower>
            <upper>0.275</upper>
            <effort>100</effort>
            <velocity>0.05</velocity>
          </limit>
          <dynamics>
            <spring_reference>0</spring_reference>
            <spring_stiffness>0</spring_stiffness>
          </dynamics>
          <use_parent_model_frame>1</use_parent_model_frame>
        </axis>
      </joint>
      <link name='fl_wheel'>
        <pose frame=''>0.14034 0.1185 0.001 0 -0 0</pose>
        <inertial>
          <pose frame=''>0 0 0 0 -0 0</pose>
          <mass>0.041913</mass>
          <inertia>
            <ixx>1.2186e-05</ixx>
            <ixy>0</ixy>
            <ixz>0</ixz>
            <iyy>1.62e-05</iyy>
            <iyz>0</iyz>
            <izz>1.2186e-05</izz>
          </inertia>
        </inertial>
        <collision name='fl_wheel_collision'>
          <pose frame=''>0 0 0 1.5708 -0 0</pose>
          <geometry>
            <cylinder>
              <length>0.031</length>
              <radius>0.03</radius>
            </cylinder>
          </geometry>
          <surface>
            <contact>
              <ode/>
            </contact>
            <friction>
              <ode>
                <mu>0</mu>
                <mu2>0</mu2>
              </ode>
              <torsional>
                <ode/>
              </torsional>
            </friction>
            <bounce/>
          </surface>
          <max_contacts>10</max_contacts>
        </collision>
        <visual name='fl_wheel_visual'>
          <pose frame=''>0 0 0 0 -0 1.5708</pose>
          <geometry>
            <mesh>
              <scale>1 1 1</scale>
              <uri>/home/joe/test_ws/src/apollo/apollo_description/meshfiles/wheel.stl</uri>
            </mesh>
          </geometry>
          <material>
            <script>
              <uri>__default__</uri>
              <name>__default__</name>
            </script>
          </material>
        </visual>
        <gravity>1</gravity>
        <velocity_decay/>
        <self_collide>0</self_collide>
        <enable_wind>0</enable_wind>
        <kinematic>0</kinematic>
      </link>
      <joint name='fl_joint' type='revolute'>
        <child>fl_wheel</child>
        <parent>base_link</parent>
        <axis>
          <xyz>0 1 0</xyz>
          <limit>
            <lower>-1e+16</lower>
            <upper>1e+16</upper>
          </limit>
          <dynamics>
            <spring_reference>0</spring_reference>
            <spring_stiffness>0</spring_stiffness>
          </dynamics>
          <use_parent_model_frame>1</use_parent_model_frame>
        </axis>
      </joint>
      <link name='fr_wheel'>
        <pose frame=''>0.14034 -0.1185 0.001 0 -0 0</pose>
        <inertial>
          <pose frame=''>0 0 0 0 -0 0</pose>
          <mass>0.041913</mass>
          <inertia>
            <ixx>1.2186e-05</ixx>
            <ixy>0</ixy>
            <ixz>0</ixz>
            <iyy>1.62e-05</iyy>
            <iyz>0</iyz>
            <izz>1.2186e-05</izz>
          </inertia>
        </inertial>
        <collision name='fr_wheel_collision'>
          <pose frame=''>0 0 0 1.5708 -0 0</pose>
          <geometry>
            <cylinder>
              <length>0.031</length>
              <radius>0.03</radius>
            </cylinder>
          </geometry>
          <surface>
            <contact>
              <ode/>
            </contact>
            <friction>
              <ode>
                <mu>0</mu>
                <mu2>0</mu2>
              </ode>
              <torsional>
                <ode/>
              </torsional>
            </friction>
            <bounce/>
          </surface>
          <max_contacts>10</max_contacts>
        </collision>
        <visual name='fr_wheel_visual'>
          <pose frame=''>0 0 0 0 -0 1.5708</pose>
          <geometry>
            <mesh>
              <scale>1 1 1</scale>
              <uri>/home/joe/test_ws/src/apollo/apollo_description/meshfiles/wheel.stl</uri>
            </mesh>
          </geometry>
          <material>
            <script>
              <uri>__default__</uri>
              <name>__default__</name>
            </script>
          </material>
        </visual>
        <gravity>1</gravity>
        <velocity_decay/>
        <self_collide>0</self_collide>
        <enable_wind>0</enable_wind>
        <kinematic>0</kinematic>
      </link>
      <joint name='fr_joint' type='revolute'>
        <child>fr_wheel</child>
        <parent>base_link</parent>
        <axis>
          <xyz>0 1 0</xyz>
          <limit>
            <lower>-1e+16</lower>
            <upper>1e+16</upper>
          </limit>
          <dynamics>
            <spring_reference>0</spring_reference>
            <spring_stiffness>0</spring_stiffness>
          </dynamics>
          <use_parent_model_frame>1</use_parent_model_frame>
        </axis>
      </joint>
      <link name='rl_wheel'>
        <pose frame=''>-0.14034 0.1185 0.001 0 -0 0</pose>
        <inertial>
          <pose frame=''>0 0 0 0 -0 0</pose>
          <mass>0.041913</mass>
          <inertia>
            <ixx>1.2186e-05</ixx>
            <ixy>0</ixy>
            <ixz>0</ixz>
            <iyy>1.62e-05</iyy>
            <iyz>0</iyz>
            <izz>1.2186e-05</izz>
          </inertia>
        </inertial>
        <collision name='rl_wheel_collision'>
          <pose frame=''>0 0 0 1.5708 -0 0</pose>
          <geometry>
            <cylinder>
              <length>0.031</length>
              <radius>0.03</radius>
            </cylinder>
          </geometry>
          <surface>
            <contact>
              <ode/>
            </contact>
            <friction>
              <ode>
                <mu>0</mu>
                <mu2>0</mu2>
              </ode>
              <torsional>
                <ode/>
              </torsional>
            </friction>
            <bounce/>
          </surface>
          <max_contacts>10</max_contacts>
        </collision>
        <visual name='rl_wheel_visual'>
          <pose frame=''>0 0 0 0 -0 1.5708</pose>
          <geometry>
            <mesh>
              <scale>1 1 1</scale>
              <uri>/home/joe/test_ws/src/apollo/apollo_description/meshfiles/wheel.stl</uri>
            </mesh>
          </geometry>
          <material>
            <script>
              <uri>__default__</uri>
              <name>__default__</name>
            </script>
          </material>
        </visual>
        <gravity>1</gravity>
        <velocity_decay/>
        <self_collide>0</self_collide>
        <enable_wind>0</enable_wind>
        <kinematic>0</kinematic>
      </link>
      <joint name='rl_joint' type='revolute'>
        <child>rl_wheel</child>
        <parent>base_link</parent>
        <axis>
          <xyz>0 1 0</xyz>
          <limit>
            <lower>-1e+16</lower>
            <upper>1e+16</upper>
          </limit>
          <dynamics>
            <spring_reference>0</spring_reference>
            <spring_stiffness>0</spring_stiffness>
          </dynamics>
          <use_parent_model_frame>1</use_parent_model_frame>
        </axis>
      </joint>
      <link name='rr_wheel'>
        <pose frame=''>-0.14034 -0.1185 0.001 0 -0 0</pose>
        <inertial>
          <pose frame=''>0 0 0 0 -0 0</pose>
          <mass>0.041913</mass>
          <inertia>
            <ixx>1.2186e-05</ixx>
            <ixy>0</ixy>
            <ixz>0</ixz>
            <iyy>1.62e-05</iyy>
            <iyz>0</iyz>
            <izz>1.2186e-05</izz>
          </inertia>
        </inertial>
        <collision name='rr_wheel_collision'>
          <pose frame=''>0 0 0 1.5708 -0 0</pose>
          <geometry>
            <cylinder>
              <length>0.031</length>
              <radius>0.03</radius>
            </cylinder>
          </geometry>
          <surface>
            <contact>
              <ode/>
            </contact>
            <friction>
              <ode>
                <mu>0</mu>
                <mu2>0</mu2>
              </ode>
              <torsional>
                <ode/>
              </torsional>
            </friction>
            <bounce/>
          </surface>
          <max_contacts>10</max_contacts>
        </collision>
        <visual name='rr_wheel_visual'>
          <pose frame=''>0 0 0 0 -0 1.5708</pose>
          <geometry>
            <mesh>
              <scale>1 1 1</scale>
              <uri>/home/joe/test_ws/src/apollo/apollo_description/meshfiles/wheel.stl</uri>
            </mesh>
          </geometry>
          <material>
            <script>
              <uri>__default__</uri>
              <name>__default__</name>
            </script>
          </material>
        </visual>
        <gravity>1</gravity>
        <velocity_decay/>
        <self_collide>0</self_collide>
        <enable_wind>0</enable_wind>
        <kinematic>0</kinematic>
      </link>
      <joint name='rr_joint' type='revolute'>
        <child>rr_wheel</child>
        <parent>base_link</parent>
        <axis>
          <xyz>0 1 0</xyz>
          <limit>
            <lower>-1e+16</lower>
            <upper>1e+16</upper>
          </limit>
          <dynamics>
            <spring_reference>0</spring_reference>
            <spring_stiffness>0</spring_stiffness>
          </dynamics>
          <use_parent_model_frame>1</use_parent_model_frame>
        </axis>
      </joint>
      <plugin name='gazebo_ros_control' filename='libgazebo_ros_control.so'>
        <robotNamespace>/</robotNamespace>
      </plugin>
      <static>0</static>
      <plugin name='ridgeback_ros_force_based_move' filename='libridgeback_ros_force_based_move.so'>
        <robotNamespace>/</robotNamespace>
        <commandTopic>apollo_velocity_controller/cmd_vel</commandTopic>
        <odometryTopic>odom</odometryTopic>
        <odometryFrame>odom</odometryFrame>
        <odometryRate>50.0</odometryRate>
        <robotBaseFrame>base_link</robotBaseFrame>
        <cmdVelTimeOut>0.25</cmdVelTimeOut>
        <publishOdometryTf>0</publishOdometryTf>
        <yaw_velocity_p_gain>500.0</yaw_velocity_p_gain>
        <x_velocity_p_gain>10000.0</x_velocity_p_gain>
        <y_velocity_p_gain>10000.0</y_velocity_p_gain>
      </plugin>
      <plugin name='imu_controller' filename='libhector_gazebo_ros_imu.so'>
        <robotNamespace>/</robotNamespace>
        <updateRate>50.0</updateRate>
        <topicName>imu/data_raw</topicName>
        <accelDrift>0.0 0.0 0.0</accelDrift>
        <accelGaussianNoise>1e-5 1e-5 0.0</accelGaussianNoise>
        <rateDrift>0.0 0.0 0.0</rateDrift>
        <rateGaussianNoise>1e-9 1e-9 1e-9</rateGaussianNoise>
        <headingDrift>0.0</headingDrift>
        <headingGaussianNoise>1e-10</headingGaussianNoise>
        <bodyName>base_link</bodyName>
        <xyzOffset>0 0 0</xyzOffset>
        <rpyOffset>0 -0 0</rpyOffset>
      </plugin>
      <plugin name='mag_controller' filename='libhector_gazebo_ros_magnetic.so'>
        <robotNamespace>/</robotNamespace>
        <updateRate>50.0</updateRate>
        <topicName>imu/mag_raw</topicName>
        <declination>4.566667</declination>
        <inclination>44.733333</inclination>
        <referenceHeading>0.0</referenceHeading>
        <magnitude>4.37559e-5</magnitude>
        <gaussianNoise>0.0000000001 0.0000000001 0.0000000001</gaussianNoise>
        <offset>1e-5 3e-6 0.0</offset>
        <drift>0.0 0.0 0.0</drift>
        <driftFrequency>0.0 0.0 0.0</driftFrequency>
        <bodyName>base_link</bodyName>
        <xyzOffset>0 0 0</xyzOffset>
        <rpyOffset>0 -0 0</rpyOffset>
      </plugin>
      <pose frame=''>0 0 0.5 0 -0 0</pose>
    </model>
    <model name='Untitled_0'>
      <link name='link_2'>
        <inertial>
          <mass>1</mass>
          <inertia>
            <ixx>0.166667</ixx>
            <ixy>0</ixy>
            <ixz>0</ixz>
            <iyy>0.166667</iyy>
            <iyz>0</iyz>
            <izz>0.166667</izz>
          </inertia>
          <pose frame=''>0 0 0 0 -0 0</pose>
        </inertial>
        <pose frame=''>-1.98457 0.39479 0 0 -0 0</pose>
        <gravity>1</gravity>
        <self_collide>0</self_collide>
        <kinematic>1</kinematic>
        <enable_wind>0</enable_wind>
        <visual name='visual'>
          <pose frame=''>0 0 0 0 -0 0</pose>
          <geometry>
            <mesh>
              <uri>/home/joe/Downloads/خره/ª⌐∞/ñ¬ƒΩƒó/ñ¬ƒΩí φ½ªí pro max/rack.stl</uri>
              <scale>1 1 1</scale>
            </mesh>
          </geometry>
          <material>
            <lighting>1</lighting>
            <script>
              <uri>file://media/materials/scripts/gazebo.material</uri>
              <name>Gazebo/Grey</name>
            </script>
            <shader type='vertex'>
              <normal_map>__default__</normal_map>
            </shader>
            <ambient>0.3 0.3 0.3 1</ambient>
            <diffuse>0.7 0.7 0.7 1</diffuse>
            <specular>0.01 0.01 0.01 1</specular>
            <emissive>0 0 0 1</emissive>
          </material>
          <transparency>0</transparency>
          <cast_shadows>1</cast_shadows>
        </visual>
        <collision name='collision'>
          <laser_retro>0</laser_retro>
          <max_contacts>10</max_contacts>
          <pose frame=''>0 0 0 0 -0 0</pose>
          <geometry>
            <mesh>
              <uri>/home/joe/Downloads/خره/ª⌐∞/ñ¬ƒΩƒó/ñ¬ƒΩí φ½ªí pro max/rack.stl</uri>
              <scale>1 1 1</scale>
            </mesh>
          </geometry>
          <surface>
            <friction>
              <ode>
                <mu>1</mu>
                <mu2>1</mu2>
                <fdir1>0 0 0</fdir1>
                <slip1>0</slip1>
                <slip2>0</slip2>
              </ode>
              <torsional>
                <coefficient>1</coefficient>
                <patch_radius>0</patch_radius>
                <surface_radius>0</surface_radius>
                <use_patch_radius>1</use_patch_radius>
                <ode>
                  <slip>0</slip>
                </ode>
              </torsional>
            </friction>
            <bounce>
              <restitution_coefficient>0</restitution_coefficient>
              <threshold>1e+06</threshold>
            </bounce>
            <contact>
              <collide_without_contact>0</collide_without_contact>
              <collide_without_contact_bitmask>1</collide_without_contact_bitmask>
              <collide_bitmask>1</collide_bitmask>
              <ode>
                <soft_cfm>0</soft_cfm>
                <soft_erp>0.2</soft_erp>
                <kp>1e+13</kp>
                <kd>1</kd>
                <max_vel>0.01</max_vel>
                <min_depth>0</min_depth>
              </ode>
              <bullet>
                <split_impulse>1</split_impulse>
                <split_impulse_penetration_threshold>-0.01</split_impulse_penetration_threshold>
                <soft_cfm>0</soft_cfm>
                <soft_erp>0.2</soft_erp>
                <kp>1e+13</kp>
                <kd>1</kd>
              </bullet>
            </contact>
          </surface>
        </collision>
      </link>
      <static>0</static>
      <allow_auto_disable>1</allow_auto_disable>
      <pose frame=''>1e-06 0 0.313225 0 -0 0</pose>
    </model>
    <state world_name='default'>
      <sim_time>506 184000000</sim_time>
      <real_time>605 387917770</real_time>
      <wall_time>1592005595 42814116</wall_time>
      <iterations>492985</iterations>
      <model name='Untitled_0'>
        <pose frame=''>0 0 0.313225 0 -0 0</pose>
        <scale>1 1 1</scale>
        <link name='link_2'>
          <pose frame=''>-1.98457 0.39479 0.313225 0 -0 0</pose>
          <velocity>0 0 0 0 -0 0</velocity>
          <acceleration>0 0 -9.8 0 -0 0</acceleration>
          <wrench>0 0 -9.8 0 -0 0</wrench>
        </link>
      </model>
      <model name='apollo'>
        <pose frame=''>-2.15245 -0.642096 0.028934 1.2e-05 2.9e-05 -1.21849</pose>
        <scale>1 1 1</scale>
        <link name='base_link'>
          <pose frame=''>-2.15245 -0.642096 0.028934 1.2e-05 2.9e-05 -1.21849</pose>
          <velocity>0 0 0.004411 0.000266 -0.00017 0</velocity>
          <acceleration>0.000544 0.000371 9.60818 -0.016544 0.18303 -0.00846</acceleration>
          <wrench>0.011486 0.007842 202.848 0 -0 0</wrench>
        </link>
        <link name='fl_wheel'>
          <pose frame=''>-1.9928 -0.732926 0.030009 3.14134 1.10502 1.92288</pose>
          <velocity>-2e-06 -2e-06 0.018692 0.047907 -0.129813 1e-06</velocity>
          <acceleration>-0.004594 -0.003637 39.4428 2.0577 -1.48771 0.000823</acceleration>
          <wrench>-0.000193 -0.000152 1.65317 0 -0 0</wrench>
        </link>
        <link name='fork'>
          <pose frame=''>-2.04086 -0.597878 0.225933 1.2e-05 2.9e-05 -1.21849</pose>
          <velocity>-3.4e-05 -5.2e-05 -0.000685 0.000268 -0.000173 1e-06</velocity>
          <acceleration>-0.013305 -0.006579 -1.37054 0 -0 0</acceleration>
          <wrench>-0.007398 -0.003658 -0.762021 0 -0 0</wrench>
        </link>
        <link name='fr_wheel'>
          <pose frame=''>-2.21525 -0.814706 0.03001 0.000355 -1.23935 -1.21883</pose>
          <velocity>-0 1e-06 0.018977 0.049983 -0.134194 -1.2e-05</velocity>
          <acceleration>-3.3e-05 0.002661 40.4335 -1.98869 -1.51432 -0.026422</acceleration>
          <wrench>-1e-06 0.000112 1.69469 0 -0 0</wrench>
        </link>
        <link name='rl_wheel'>
          <pose frame=''>-2.08966 -0.469486 0.030008 0.000168 -0.959093 -1.21863</pose>
          <velocity>1e-06 -1e-06 0.017603 0.035589 -0.093739 1e-06</velocity>
          <acceleration>0.002222 -0.000676 36.4818 -0.134165 0.066257 0.000779</acceleration>
          <wrench>9.3e-05 -2.8e-05 1.52906 0 -0 0</wrench>
        </link>
        <link name='rr_wheel'>
          <pose frame=''>-2.3121 -0.551266 0.030009 3.14138 1.04151 1.92292</pose>
          <velocity>0 -0 0.01806 0.041141 -0.11006 -1.2e-05</velocity>
          <acceleration>0.00062 0.000372 37.6458 0.368918 1.3347 -0.023604</acceleration>
          <wrench>2.6e-05 1.6e-05 1.57785 0 -0 0</wrench>
        </link>
      </model>
      <model name='ground_plane'>
        <pose frame=''>0 0 0 0 -0 0</pose>
        <scale>1 1 1</scale>
        <link name='link'>
          <pose frame=''>0 0 0 0 -0 0</pose>
          <velocity>0 0 0 0 -0 0</velocity>
          <acceleration>0 0 0 0 -0 0</acceleration>
          <wrench>0 0 0 0 -0 0</wrench>
        </link>
      </model>
      <model name='unit_box'>
        <pose frame=''>-2.26471 -0.134188 0.089368 3.14159 5e-06 1.51877</pose>
        <scale>1 1 1</scale>
        <link name='link'>
          <pose frame=''>-2.26471 -0.134188 0.089368 3.14159 5e-06 1.51877</pose>
          <velocity>0 0 0 0 -0 0</velocity>
          <acceleration>0 0 -9.8 0 -0 0</acceleration>
          <wrench>0 0 -9.8 0 -0 0</wrench>
        </link>
      </model>
      <light name='sun'>
        <pose frame=''>0 0 10 0 -0 0</pose>
      </light>
    </state>
    <gui fullscreen='0'>
      <camera name='user_camera'>
        <pose frame=''>-3.02012 -0.949975 0.7842 0 0.532949 0.592842</pose>
        <view_controller>orbit</view_controller>
        <projection_type>perspective</projection_type>
      </camera>
    </gui>
    <model name='unit_box'>
      <link name='link'>
        <inertial>
          <mass>1</mass>
          <inertia>
            <ixx>0.166667</ixx>
            <ixy>0</ixy>
            <ixz>0</ixz>
            <iyy>0.166667</iyy>
            <iyz>0</iyz>
            <izz>0.166667</izz>
          </inertia>
          <pose frame=''>0 0 0 0 -0 0</pose>
        </inertial>
        <self_collide>0</self_collide>
        <enable_wind>0</enable_wind>
        <kinematic>0</kinematic>
        <pose frame=''>0 0 0 0 -0 0</pose>
        <gravity>1</gravity>
        <visual name='visual'>
          <geometry>
            <box>
              <size>0.469028 0.304195 0.206661</size>
            </box>
          </geometry>
          <material>
            <script>
              <name>Gazebo/Grey</name>
              <uri>file://media/materials/scripts/gazebo.material</uri>
            </script>
            <ambient>0.3 0.3 0.3 1</ambient>
            <diffuse>0.7 0.7 0.7 1</diffuse>
            <specular>0.01 0.01 0.01 1</specular>
            <emissive>0 0 0 1</emissive>
            <shader type='vertex'>
              <normal_map>__default__</normal_map>
            </shader>
          </material>
          <pose frame=''>0 0 0 0 -0 0</pose>
          <transparency>0</transparency>
          <cast_shadows>1</cast_shadows>
        </visual>
        <collision name='collision'>
          <laser_retro>0</laser_retro>
          <max_contacts>10</max_contacts>
          <pose frame=''>0 0 -0.05 0 -0 0</pose>
          <geometry>
            <mesh>
              <uri>/home/joe/Downloads/خره/ª⌐∞/Racks/doubleColumnRack/productOnPallet.stl</uri>
              <scale>2 1 1.5</scale>
            </mesh>
          </geometry>
          <surface>
            <friction>
              <ode>
                <mu>1</mu>
                <mu2>1</mu2>
                <fdir1>0 0 0</fdir1>
                <slip1>0</slip1>
                <slip2>0</slip2>
              </ode>
              <torsional>
                <coefficient>1</coefficient>
                <patch_radius>0</patch_radius>
                <surface_radius>0</surface_radius>
                <use_patch_radius>1</use_patch_radius>
                <ode>
                  <slip>0</slip>
                </ode>
              </torsional>
            </friction>
            <bounce>
              <restitution_coefficient>0</restitution_coefficient>
              <threshold>1e+06</threshold>
            </bounce>
            <contact>
              <collide_without_contact>0</collide_without_contact>
              <collide_without_contact_bitmask>1</collide_without_contact_bitmask>
              <collide_bitmask>1</collide_bitmask>
              <ode>
                <soft_cfm>0</soft_cfm>
                <soft_erp>0.2</soft_erp>
                <kp>1e+13</kp>
                <kd>1</kd>
                <max_vel>0.01</max_vel>
                <min_depth>0</min_depth>
              </ode>
              <bullet>
                <split_impulse>1</split_impulse>
                <split_impulse_penetration_threshold>-0.01</split_impulse_penetration_threshold>
                <soft_cfm>0</soft_cfm>
                <soft_erp>0.2</soft_erp>
                <kp>1e+13</kp>
                <kd>1</kd>
              </bullet>
            </contact>
          </surface>
        </collision>
      </link>
      <static>0</static>
      <allow_auto_disable>1</allow_auto_disable>
      <pose frame=''>-1.81766 -2.06447 0.10333 0 -0 2.4e-05</pose>
    </model>
  </world>
</sdf>
